{
    "imageDivider": {
        "2024-01-27 22:19:44": {
            "ExceptionName": "cannot identify image file <_io.BytesIO object at 0x0000016F6882F3D0>",
            "Traceback": [
                "Traceback (most recent call last):",
                "  File \"H:\\icreo\\lol\\bot\\main.py\", line 105, in Step1",
                "    image = Image.open(binary).convert(\"RGBA\")",
                "  File \"C:\\Users\\909090\\AppData\\Local\\Programs\\Python\\Python310\\lib\\site-packages\\PIL\\Image.py\", line 3280, in open",
                "    raise UnidentifiedImageError(msg)",
                "PIL.UnidentifiedImageError: cannot identify image file <_io.BytesIO object at 0x0000016F6882F3D0>"
            ]
        },
        "2024-01-27 22:20:53": {
            "ExceptionName": "cannot identify image file <_io.BytesIO object at 0x0000016B9B34BFB0>",
            "Traceback": [
                "Traceback (most recent call last):",
                "  File \"H:\\icreo\\lol\\bot\\main.py\", line 105, in Step1",
                "    image = Image.open(binary)",
                "  File \"C:\\Users\\909090\\AppData\\Local\\Programs\\Python\\Python310\\lib\\site-packages\\PIL\\Image.py\", line 3280, in open",
                "    raise UnidentifiedImageError(msg)",
                "PIL.UnidentifiedImageError: cannot identify image file <_io.BytesIO object at 0x0000016B9B34BFB0>"
            ]
        },
        "2024-01-27 22:21:20": {
            "ExceptionName": "cannot identify image file <_io.BytesIO object at 0x000001DEEF03BEC0>",
            "Traceback": [
                "Traceback (most recent call last):",
                "  File \"H:\\icreo\\lol\\bot\\main.py\", line 105, in Step1",
                "    image = Image.open(binary)",
                "  File \"C:\\Users\\909090\\AppData\\Local\\Programs\\Python\\Python310\\lib\\site-packages\\PIL\\Image.py\", line 3280, in open",
                "    raise UnidentifiedImageError(msg)",
                "PIL.UnidentifiedImageError: cannot identify image file <_io.BytesIO object at 0x000001DEEF03BEC0>"
            ]
        },
        "2024-01-27 22:22:00": {
            "ExceptionName": "cannot identify image file <_io.BytesIO object at 0x000001DEEF03BCE0>",
            "Traceback": [
                "Traceback (most recent call last):",
                "  File \"H:\\icreo\\lol\\bot\\main.py\", line 105, in Step1",
                "    image = Image.open(binary)",
                "  File \"C:\\Users\\909090\\AppData\\Local\\Programs\\Python\\Python310\\lib\\site-packages\\PIL\\Image.py\", line 3280, in open",
                "    raise UnidentifiedImageError(msg)",
                "PIL.UnidentifiedImageError: cannot identify image file <_io.BytesIO object at 0x000001DEEF03BCE0>"
            ]
        },
        "2024-01-27 22:23:02": {
            "ExceptionName": "cannot identify image file <_io.BytesIO object at 0x000001CE8DA4EFC0>",
            "Traceback": [
                "Traceback (most recent call last):",
                "  File \"H:\\icreo\\lol\\bot\\main.py\", line 105, in Step1",
                "    image = Image.open(binary).convert(\"RGBA\")",
                "  File \"C:\\Users\\909090\\AppData\\Local\\Programs\\Python\\Python310\\lib\\site-packages\\PIL\\Image.py\", line 3280, in open",
                "    raise UnidentifiedImageError(msg)",
                "PIL.UnidentifiedImageError: cannot identify image file <_io.BytesIO object at 0x000001CE8DA4EFC0>"
            ]
        },
        "2024-01-27 22:25:43": {
            "ExceptionName": "cannot identify image file <_io.BytesIO object at 0x000001CEA4A52250>",
            "Traceback": [
                "Traceback (most recent call last):",
                "  File \"H:\\icreo\\lol\\bot\\main.py\", line 105, in Step1",
                "    image = Image.open(binary).convert(\"RGBA\")",
                "  File \"C:\\Users\\909090\\AppData\\Local\\Programs\\Python\\Python310\\lib\\site-packages\\PIL\\Image.py\", line 3280, in open",
                "    raise UnidentifiedImageError(msg)",
                "PIL.UnidentifiedImageError: cannot identify image file <_io.BytesIO object at 0x000001CEA4A52250>"
            ]
        },
        "2024-01-27 22:25:48": {
            "ExceptionName": "cannot identify image file <_io.BytesIO object at 0x000001CEA453E4D0>",
            "Traceback": [
                "Traceback (most recent call last):",
                "  File \"H:\\icreo\\lol\\bot\\main.py\", line 105, in Step1",
                "    image = Image.open(binary).convert(\"RGBA\")",
                "  File \"C:\\Users\\909090\\AppData\\Local\\Programs\\Python\\Python310\\lib\\site-packages\\PIL\\Image.py\", line 3280, in open",
                "    raise UnidentifiedImageError(msg)",
                "PIL.UnidentifiedImageError: cannot identify image file <_io.BytesIO object at 0x000001CEA453E4D0>"
            ]
        },
        "2024-01-27 22:30:59": {
            "ExceptionName": "Telegram server says - Internal Server Error",
            "Traceback": [
                "Traceback (most recent call last):",
                "  File \"H:\\icreo\\lol\\bot\\main.py\", line 215, in Step2",
                "    await bot.send_photo(data[\"idChat\"], photo=BufferedInputFile(image_buffer.getvalue(), filename='photo.png'), caption=\"*\u041f\u043e\u0434\u0442\u0432\u0435\u0440\u0436\u0434\u0430\u0435\u0442\u0435 \u0440\u0430\u0437\u0440\u0435\u0437\u043a\u0443?*\", reply_markup=markups.Accept(), parse_mode=\"Markdown\")",
                "  File \"C:\\Users\\909090\\AppData\\Local\\Programs\\Python\\Python310\\lib\\site-packages\\aiogram\\client\\bot.py\", line 2764, in send_photo",
                "    return await self(call, request_timeout=request_timeout)",
                "  File \"C:\\Users\\909090\\AppData\\Local\\Programs\\Python\\Python310\\lib\\site-packages\\aiogram\\client\\bot.py\", line 432, in __call__",
                "    return await self.session(self, method, timeout=request_timeout)",
                "  File \"C:\\Users\\909090\\AppData\\Local\\Programs\\Python\\Python310\\lib\\site-packages\\aiogram\\client\\session\\base.py\", line 257, in __call__",
                "    return cast(TelegramType, await middleware(bot, method))",
                "  File \"C:\\Users\\909090\\AppData\\Local\\Programs\\Python\\Python310\\lib\\site-packages\\aiogram\\client\\session\\aiohttp.py\", line 175, in make_request",
                "    response = self.check_response(",
                "  File \"C:\\Users\\909090\\AppData\\Local\\Programs\\Python\\Python310\\lib\\site-packages\\aiogram\\client\\session\\base.py\", line 134, in check_response",
                "    raise TelegramServerError(method=method, message=description)",
                "aiogram.exceptions.TelegramServerError: Telegram server says - Internal Server Error"
            ]
        },
        "2024-06-14 02:17:33": {
            "ExceptionName": "Telegram server says - Bad Request: message to edit not found",
            "Traceback": [
                "Traceback (most recent call last):",
                "  File \"H:\\icreo\\lol\\bot\\main.py\", line 181, in Cutter",
                "    await bot.edit_message_text(text=f\"_\u041e\u0441\u0442\u0430\u043b\u043e\u0441\u044c \u0441\u0435\u043a\u0443\u043d\u0434\u043e\u0447\u043a\u0430._ \\n*\u041f\u0440\u043e\u0433\u0440\u0435\u0441\u0441: 100%*\",",
                "  File \"C:\\Users\\909090\\AppData\\Local\\Programs\\Python\\Python310\\lib\\site-packages\\aiogram\\client\\bot.py\", line 1475, in edit_message_text",
                "    return await self(call, request_timeout=request_timeout)",
                "  File \"C:\\Users\\909090\\AppData\\Local\\Programs\\Python\\Python310\\lib\\site-packages\\aiogram\\client\\bot.py\", line 432, in __call__",
                "    return await self.session(self, method, timeout=request_timeout)",
                "  File \"C:\\Users\\909090\\AppData\\Local\\Programs\\Python\\Python310\\lib\\site-packages\\aiogram\\client\\session\\base.py\", line 257, in __call__",
                "    return cast(TelegramType, await middleware(bot, method))",
                "  File \"C:\\Users\\909090\\AppData\\Local\\Programs\\Python\\Python310\\lib\\site-packages\\aiogram\\client\\session\\aiohttp.py\", line 175, in make_request",
                "    response = self.check_response(",
                "  File \"C:\\Users\\909090\\AppData\\Local\\Programs\\Python\\Python310\\lib\\site-packages\\aiogram\\client\\session\\base.py\", line 120, in check_response",
                "    raise TelegramBadRequest(method=method, message=description)",
                "aiogram.exceptions.TelegramBadRequest: Telegram server says - Bad Request: message to edit not found"
            ]
        },
        "2024-06-29 17:46:31": {
            "ExceptionName": "cannot identify image file <_io.BytesIO object at 0x00000213C1F06930>",
            "Traceback": [
                "Traceback (most recent call last):",
                "  File \"H:\\icreo\\lol\\bot\\main.py\", line 110, in Step1",
                "    image = Image.open(binary).convert(\"RGBA\")",
                "  File \"C:\\Users\\909090\\AppData\\Local\\Programs\\Python\\Python310\\lib\\site-packages\\PIL\\Image.py\", line 3280, in open",
                "    raise UnidentifiedImageError(msg)",
                "PIL.UnidentifiedImageError: cannot identify image file <_io.BytesIO object at 0x00000213C1F06930>"
            ]
        },
        "2024-06-29 17:46:42": {
            "ExceptionName": "cannot identify image file <_io.BytesIO object at 0x00000213C1B33740>",
            "Traceback": [
                "Traceback (most recent call last):",
                "  File \"H:\\icreo\\lol\\bot\\main.py\", line 110, in Step1",
                "    image = Image.open(binary).convert(\"RGBA\")",
                "  File \"C:\\Users\\909090\\AppData\\Local\\Programs\\Python\\Python310\\lib\\site-packages\\PIL\\Image.py\", line 3280, in open",
                "    raise UnidentifiedImageError(msg)",
                "PIL.UnidentifiedImageError: cannot identify image file <_io.BytesIO object at 0x00000213C1B33740>"
            ]
        }
    }
}